Workbook
Name RETA_MONTHLY: Constants!$B$5
Name RETA_ANNUAL: Constants!$B$6
Name MINIMO_PERSONAL: Constants!$B$9
Name MINIMO_DESCENDIENTES: Constants!$B$10
Name GASTOS_DIFICIL_RATE: Constants!$B$13
Name GASTOS_DIFICIL_MAX: Constants!$B$14
Name PRIVATE_COSTS: Constants!$B$17

Sheet Overview
A1: Spanish Autonomo Tax Calculator
A2: Fiscal Year 2025/2026
A4: Quick Navigation
A5: Scenario A - 3K
A6: Scenario B - 6K
A7: Scenario C - 9K
A8: Scenario D - 12K
A9: Scenario E - 18K
A10: Constants (Fiscal Data)
A12: Scenario Comparison
A13: Metric | B13: A | C13: B | D13: C | E13: D | F13: E
A14: Monthly Revenue | B14: ='Scenario A - 3K'!B3 | C14: ='Scenario B - 6K'!B3 | D14: ='Scenario C - 9K'!B3 | E14: ='Scenario D - 12K'!B3 | F14: ='Scenario E - 18K'!B3
A15: Monthly Expenses | B15: ='Scenario A - 3K'!B4 | C15: ='Scenario B - 6K'!B4 | D15: ='Scenario C - 9K'!B4 | E15: ='Scenario D - 12K'!B4 | F15: ='Scenario E - 18K'!B4
A16: Belgium Pattern | B16: ='Scenario A - 3K'!B5 | C16: ='Scenario B - 6K'!B5 | D16: ='Scenario C - 9K'!B5 | E16: ='Scenario D - 12K'!B5 | F16: ='Scenario E - 18K'!B5
A18: Annual Revenue | B18: ='Scenario A - 3K'!B10 | C18: ='Scenario B - 6K'!B10 | D18: ='Scenario C - 9K'!B10 | E18: ='Scenario D - 12K'!B10 | F18: ='Scenario E - 18K'!B10
A19: Total Deductible | B19: ='Scenario A - 3K'!B15 | C19: ='Scenario B - 6K'!B15 | D19: ='Scenario C - 9K'!B15 | E19: ='Scenario D - 12K'!B15 | F19: ='Scenario E - 18K'!B15
A20: Base Liquidable | B20: ='Scenario A - 3K'!B22 | C20: ='Scenario B - 6K'!B22 | D20: ='Scenario C - 9K'!B22 | E20: ='Scenario D - 12K'!B22 | F20: ='Scenario E - 18K'!B22
A22: Annual IRPF | B22: ='Scenario A - 3K'!B47 | C22: ='Scenario B - 6K'!B47 | D22: ='Scenario C - 9K'!B47 | E22: ='Scenario D - 12K'!B47 | F22: ='Scenario E - 18K'!B47
A23: Monthly IRPF | B23: ='Scenario A - 3K'!B48 | C23: ='Scenario B - 6K'!B48 | D23: ='Scenario C - 9K'!B48 | E23: ='Scenario D - 12K'!B48 | F23: ='Scenario E - 18K'!B48
A24: Effective Tax Rate | B24: ='Scenario A - 3K'!B53 | C24: ='Scenario B - 6K'!B53 | D24: ='Scenario C - 9K'!B53 | E24: ='Scenario D - 12K'!B53 | F24: ='Scenario E - 18K'!B53
A26: Annual Net Income | B26: ='Scenario A - 3K'!B49 | C26: ='Scenario B - 6K'!B49 | D26: ='Scenario C - 9K'!B49 | E26: ='Scenario D - 12K'!B49 | F26: ='Scenario E - 18K'!B49
A27: Monthly Net Income | B27: ='Scenario A - 3K'!B50 | C27: ='Scenario B - 6K'!B50 | D27: ='Scenario C - 9K'!B50 | E27: ='Scenario D - 12K'!B50 | F27: ='Scenario E - 18K'!B50
A28: Annual Leefgeld | B28: ='Scenario A - 3K'!B51 | C28: ='Scenario B - 6K'!B51 | D28: ='Scenario C - 9K'!B51 | E28: ='Scenario D - 12K'!B51 | F28: ='Scenario E - 18K'!B51
A29: Monthly Leefgeld | B29: ='Scenario A - 3K'!B52 | C29: ='Scenario B - 6K'!B52 | D29: ='Scenario C - 9K'!B52 | E29: ='Scenario D - 12K'!B52 | F29: ='Scenario E - 18K'!B52

Sheet Scenario A - 3K
A1: INPUTS (Edit these values)
A3: Monthly Revenue | B3: 3000
A4: Monthly Expenses | B4: 750
A5: Belgium Pattern | B5: 1000
A6: Spain Deductible | B6: 383
A8: ANNUAL CALCULATIONS
A10: Annual Revenue | B10: =B3*12
A11: Annual Expenses | B11: =B4*12
A12: Annual Belgium Costs | B12: =B5*12
A13: Annual Spain Deductible | B13: =B6*12
A14: RETA Annual | B14: =RETA_ANNUAL
A15: Total Deductible | B15: =SUM(B11:B14)
A16: Rendimiento Neto Previo | B16: =B10-B15
A18: GASTOS DE DIFICIL JUSTIFICACION
A20: Rendimiento Neto Previo | B20: =B16
A21: Gastos Dificil (5%) | B21: =MIN(MAX(0,B16)*GASTOS_DIFICIL_RATE,GASTOS_DIFICIL_MAX)
A22: Base Liquidable | B22: =MAX(0,B16-B21)
A24: IRPF BRACKET CALCULATION
A25: Lower | B25: Upper | C25: Rate | D25: Taxable | E25: Tax
A26: 0 | B26: 12450 | C26: 0.19 | D26: =MAX(0,MIN($B$22,12450)-0) | E26: =D26*C26
A27: 12450 | B27: 20200 | C27: 0.24 | D27: =MAX(0,MIN($B$22,20200)-12450) | E27: =D27*C27
A28: 20200 | B28: 35200 | C28: 0.3 | D28: =MAX(0,MIN($B$22,35200)-20200) | E28: =D28*C28
A29: 35200 | B29: 60000 | C29: 0.37 | D29: =MAX(0,MIN($B$22,60000)-35200) | E29: =D29*C29
A30: 60000 | B30: 300000 | C30: 0.45 | D30: =MAX(0,MIN($B$22,300000)-60000) | E30: =D30*C30
A31: 300000 | B31: + | C31: 0.47 | D31: =MAX(0,MIN($B$22,999999999)-300000) | E31: =D31*C31
A32: Total Tax (Cuota 1) | E32: =SUM(E26:E31)
A34: 4-PHASE MINIMO METHOD
A36: Base Liquidable | B36: =B22
A37: Tax on Base (Cuota 1) | B37: =E32
A38: Minimo Personal | B38: =MINIMO_PERSONAL
A39: Minimo Descendientes | B39: =MINIMO_DESCENDIENTES
A40: Total Minimos | B40: =B38+B39
A41: Tax on Minimos (Cuota 3) | B41: =B40*0.19
A42: Cuota Integra | B42: =MAX(0,B37-B41)
A43: Cuota Diferencial | B43: =B42
A45: FINAL RESULTS
A47: Annual IRPF | B47: =B43
A48: Monthly IRPF | B48: =B47/12
A49: Annual Net Income | B49: =B10-B15-B47
A50: Monthly Net Income | B50: =B49/12
...

Sheet Scenario B - 6K
A1: INPUTS (Edit these values)
A3: Monthly Revenue | B3: 6000
A4: Monthly Expenses | B4: 1500
A5: Belgium Pattern | B5: 1000
A6: Spain Deductible | B6: 383
A8: ANNUAL CALCULATIONS
A10: Annual Revenue | B10: =B3*12
A11: Annual Expenses | B11: =B4*12
A12: Annual Belgium Costs | B12: =B5*12
A13: Annual Spain Deductible | B13: =B6*12
A14: RETA Annual | B14: =RETA_ANNUAL
A15: Total Deductible | B15: =SUM(B11:B14)
A16: Rendimiento Neto Previo | B16: =B10-B15
A18: GASTOS DE DIFICIL JUSTIFICACION
A20: Rendimiento Neto Previo | B20: =B16
A21: Gastos Dificil (5%) | B21: =MIN(MAX(0,B16)*GASTOS_DIFICIL_RATE,GASTOS_DIFICIL_MAX)
A22: Base Liquidable | B22: =MAX(0,B16-B21)
A24: IRPF BRACKET CALCULATION
A25: Lower | B25: Upper | C25: Rate | D25: Taxable | E25: Tax
A26: 0 | B26: 12450 | C26: 0.19 | D26: =MAX(0,MIN($B$22,12450)-0) | E26: =D26*C26
A27: 12450 | B27: 20200 | C27: 0.24 | D27: =MAX(0,MIN($B$22,20200)-12450) | E27: =D27*C27
A28: 20200 | B28: 35200 | C28: 0.3 | D28: =MAX(0,MIN($B$22,35200)-20200) | E28: =D28*C28
A29: 35200 | B29: 60000 | C29: 0.37 | D29: =MAX(0,MIN($B$22,60000)-35200) | E29: =D29*C29
A30: 60000 | B30: 300000 | C30: 0.45 | D30: =MAX(0,MIN($B$22,300000)-60000) | E30: =D30*C30
A31: 300000 | B31: + | C31: 0.47 | D31: =MAX(0,MIN($B$22,999999999)-300000) | E31: =D31*C31
A32: Total Tax (Cuota 1) | E32: =SUM(E26:E31)
A34: 4-PHASE MINIMO METHOD
A36: Base Liquidable | B36: =B22
A37: Tax on Base (Cuota 1) | B37: =E32
A38: Minimo Personal | B38: =MINIMO_PERSONAL
A39: Minimo Descendientes | B39: =MINIMO_DESCENDIENTES
A40: Total Minimos | B40: =B38+B39
A41: Tax on Minimos (Cuota 3) | B41: =B40*0.19
A42: Cuota Integra | B42: =MAX(0,B37-B41)
A43: Cuota Diferencial | B43: =B42
A45: FINAL RESULTS
A47: Annual IRPF | B47: =B43
A48: Monthly IRPF | B48: =B47/12
A49: Annual Net Income | B49: =B10-B15-B47
A50: Monthly Net Income | B50: =B49/12
...

Sheet Scenario C - 9K
A1: INPUTS (Edit these values)
A3: Monthly Revenue | B3: 9000
A4: Monthly Expenses | B4: 3000
A5: Belgium Pattern | B5: 2500
A6: Spain Deductible | B6: 383
A8: ANNUAL CALCULATIONS
A10: Annual Revenue | B10: =B3*12
A11: Annual Expenses | B11: =B4*12
A12: Annual Belgium Costs | B12: =B5*12
A13: Annual Spain Deductible | B13: =B6*12
A14: RETA Annual | B14: =RETA_ANNUAL
A15: Total Deductible | B15: =SUM(B11:B14)
A16: Rendimiento Neto Previo | B16: =B10-B15
A18: GASTOS DE DIFICIL JUSTIFICACION
A20: Rendimiento Neto Previo | B20: =B16
A21: Gastos Dificil (5%) | B21: =MIN(MAX(0,B16)*GASTOS_DIFICIL_RATE,GASTOS_DIFICIL_MAX)
A22: Base Liquidable | B22: =MAX(0,B16-B21)
A24: IRPF BRACKET CALCULATION
A25: Lower | B25: Upper | C25: Rate | D25: Taxable | E25: Tax
A26: 0 | B26: 12450 | C26: 0.19 | D26: =MAX(0,MIN($B$22,12450)-0) | E26: =D26*C26
A27: 12450 | B27: 20200 | C27: 0.24 | D27: =MAX(0,MIN($B$22,20200)-12450) | E27: =D27*C27
A28: 20200 | B28: 35200 | C28: 0.3 | D28: =MAX(0,MIN($B$22,35200)-20200) | E28: =D28*C28
A29: 35200 | B29: 60000 | C29: 0.37 | D29: =MAX(0,MIN($B$22,60000)-35200) | E29: =D29*C29
A30: 60000 | B30: 300000 | C30: 0.45 | D30: =MAX(0,MIN($B$22,300000)-60000) | E30: =D30*C30
A31: 300000 | B31: + | C31: 0.47 | D31: =MAX(0,MIN($B$22,999999999)-300000) | E31: =D31*C31
A32: Total Tax (Cuota 1) | E32: =SUM(E26:E31)
A34: 4-PHASE MINIMO METHOD
A36: Base Liquidable | B36: =B22
A37: Tax on Base (Cuota 1) | B37: =E32
A38: Minimo Personal | B38: =MINIMO_PERSONAL
A39: Minimo Descendientes | B39: =MINIMO_DESCENDIENTES
A40: Total Minimos | B40: =B38+B39
A41: Tax on Minimos (Cuota 3) | B41: =B40*0.19
A42: Cuota Integra | B42: =MAX(0,B37-B41)
A43: Cuota Diferencial | B43: =B42
A45: FINAL RESULTS
A47: Annual IRPF | B47: =B43
A48: Monthly IRPF | B48: =B47/12
A49: Annual Net Income | B49: =B10-B15-B47
A50: Monthly Net Income | B50: =B49/12
...

Sheet Scenario D - 12K
A1: INPUTS (Edit these values)
A3: Monthly Revenue | B3: 12000
A4: Monthly Expenses | B4: 5000
A5: Belgium Pattern | B5: 2500
A6: Spain Deductible | B6: 383
A8: ANNUAL CALCULATIONS
A10: Annual Revenue | B10: =B3*12
A11: Annual Expenses | B11: =B4*12
A12: Annual Belgium Costs | B12: =B5*12
A13: Annual Spain Deductible | B13: =B6*12
A14: RETA Annual | B14: =RETA_ANNUAL
A15: Total Deductible | B15: =SUM(B11:B14)
A16: Rendimiento Neto Previo | B16: =B10-B15
A18: GASTOS DE DIFICIL JUSTIFICACION
A20: Rendimiento Neto Previo | B20: =B16
A21: Gastos Dificil (5%) | B21: =MIN(MAX(0,B16)*GASTOS_DIFICIL_RATE,GASTOS_DIFICIL_MAX)
A22: Base Liquidable | B22: =MAX(0,B16-B21)
A24: IRPF BRACKET CALCULATION
A25: Lower | B25: Upper | C25: Rate | D25: Taxable | E25: Tax
A26: 0 | B26: 12450 | C26: 0.19 | D26: =MAX(0,MIN($B$22,12450)-0) | E26: =D26*C26
A27: 12450 | B27: 20200 | C27: 0.24 | D27: =MAX(0,MIN($B$22,20200)-12450) | E27: =D27*C27
A28: 20200 | B28: 35200 | C28: 0.3 | D28: =MAX(0,MIN($B$22,35200)-20200) | E28: =D28*C28
A29: 35200 | B29: 60000 | C29: 0.37 | D29: =MAX(0,MIN($B$22,60000)-35200) | E29: =D29*C29
A30: 60000 | B30: 300000 | C30: 0.45 | D30: =MAX(0,MIN($B$22,300000)-60000) | E30: =D30*C30
A31: 300000 | B31: + | C31: 0.47 | D31: =MAX(0,MIN($B$22,999999999)-300000) | E31: =D31*C31
A32: Total Tax (Cuota 1) | E32: =SUM(E26:E31)
A34: 4-PHASE MINIMO METHOD
A36: Base Liquidable | B36: =B22
A37: Tax on Base (Cuota 1) | B37: =E32
A38: Minimo Personal | B38: =MINIMO_PERSONAL
A39: Minimo Descendientes | B39: =MINIMO_DESCENDIENTES
A40: Total Minimos | B40: =B38+B39
A41: Tax on Minimos (Cuota 3) | B41: =B40*0.19
A42: Cuota Integra | B42: =MAX(0,B37-B41)
A43: Cuota Diferencial | B43: =B42
A45: FINAL RESULTS
A47: Annual IRPF | B47: =B43
A48: Monthly IRPF | B48: =B47/12
A49: Annual Net Income | B49: =B10-B15-B47
A50: Monthly Net Income | B50: =B49/12
...

Sheet Scenario E - 18K
A1: INPUTS (Edit these values)
A3: Monthly Revenue | B3: 18000
A4: Monthly Expenses | B4: 8000
A5: Belgium Pattern | B5: 2500
A6: Spain Deductible | B6: 383
A8: ANNUAL CALCULATIONS
A10: Annual Revenue | B10: =B3*12
A11: Annual Expenses | B11: =B4*12
A12: Annual Belgium Costs | B12: =B5*12
A13: Annual Spain Deductible | B13: =B6*12
A14: RETA Annual | B14: =RETA_ANNUAL
A15: Total Deductible | B15: =SUM(B11:B14)
A16: Rendimiento Neto Previo | B16: =B10-B15
A18: GASTOS DE DIFICIL JUSTIFICACION
A20: Rendimiento Neto Previo | B20: =B16
A21: Gastos Dificil (5%) | B21: =MIN(MAX(0,B16)*GASTOS_DIFICIL_RATE,GASTOS_DIFICIL_MAX)
A22: Base Liquidable | B22: =MAX(0,B16-B21)
A24: IRPF BRACKET CALCULATION
A25: Lower | B25: Upper | C25: Rate | D25: Taxable | E25: Tax
A26: 0 | B26: 12450 | C26: 0.19 | D26: =MAX(0,MIN($B$22,12450)-0) | E26: =D26*C26
A27: 12450 | B27: 20200 | C27: 0.24 | D27: =MAX(0,MIN($B$22,20200)-12450) | E27: =D27*C27
A28: 20200 | B28: 35200 | C28: 0.3 | D28: =MAX(0,MIN($B$22,35200)-20200) | E28: =D28*C28
A29: 35200 | B29: 60000 | C29: 0.37 | D29: =MAX(0,MIN($B$22,60000)-35200) | E29: =D29*C29
A30: 60000 | B30: 300000 | C30: 0.45 | D30: =MAX(0,MIN($B$22,300000)-60000) | E30: =D30*C30
A31: 300000 | B31: + | C31: 0.47 | D31: =MAX(0,MIN($B$22,999999999)-300000) | E31: =D31*C31
A32: Total Tax (Cuota 1) | E32: =SUM(E26:E31)
A34: 4-PHASE MINIMO METHOD
A36: Base Liquidable | B36: =B22
A37: Tax on Base (Cuota 1) | B37: =E32
A38: Minimo Personal | B38: =MINIMO_PERSONAL
A39: Minimo Descendientes | B39: =MINIMO_DESCENDIENTES
A40: Total Minimos | B40: =B38+B39
A41: Tax on Minimos (Cuota 3) | B41: =B40*0.19
A42: Cuota Integra | B42: =MAX(0,B37-B41)
A43: Cuota Diferencial | B43: =B42
A45: FINAL RESULTS
A47: Annual IRPF | B47: =B43
A48: Monthly IRPF | B48: =B47/12
A49: Annual Net Income | B49: =B10-B15-B47
A50: Monthly Net Income | B50: =B49/12
...

Sheet Constants
A1: Fiscal Data 2025/2026
A2: Sources: AEAT, BOE, Seguridad Social
A4: RETA (Seguridad Social)
A5: RETA Monthly | B5: 428.4
A6: RETA Annual | B6: =RETA_MONTHLY*12
A8: Minimos Personales y Familiares
A9: Minimo Personal | B9: 5550
A10: Minimo Descendientes (1) | B10: 2400
A12: Gastos de Dificil Justificacion
A13: Gastos Dificil Rate | B13: 0.05
A14: Gastos Dificil Max | B14: 2000
A16: Private Costs (Non-Deductible)
A17: Private Costs Monthly | B17: 1727
A19: IRPF 2025 Brackets
A20: Lower | B20: Upper | C20: Rate | D20: Base Tax
A21: 0 | B21: 12450 | C21: 0.19 | D21: 0
A22: 12450 | B22: 20200 | C22: 0.24 | D22: 2365.5
A23: 20200 | B23: 35200 | C23: 0.3 | D23: 4225.5
A24: 35200 | B24: 60000 | C24: 0.37 | D24: 8725.5
A25: 60000 | B25: 300000 | C25: 0.45 | D25: 17901.5
A26: 300000 | B26: + | C26: 0.47 | D26: 125901.5
A28: Notes:
A29: - RETA cuota is fixed from registration (not theoretical tramo)
A30: - Gastos dificil: 5% (not 7% - that was exceptional 2023)
A31: - Update these values for 2027 rates when available
